Workbook
Name UPDATE: 'Data Sheet'!$E$1

Sheet One Page View
B2: ='Data Sheet'!B1 & " - One Page View" -> EICHER MOTORS LTD - One Page View
C4: =data!C23 -> Eicher Motors Limited is an Indian multinational automotive company that manufactures motorcycles and commercial vehicles, headquartered in New Delhi. Eicher is the parent company of Royal Enfield, a manufacturer of middleweight motorcycles. It also manufactures Eicher branded trucks and buses, under a joint venture with Volvo Group.
B6: Key Financial Metrics | C6: =IFERROR('Data Sheet'!G16,0) -> 44286 | D6: =IFERROR('Data Sheet'!H16,0) -> 44651 | E6: =IFERROR('Data Sheet'!I16,0) -> 45016 | F6: =IFERROR('Data Sheet'!J16,0) -> 45382 | G6: =IFERROR('Data Sheet'!K16,0) -> 45747 | I6: Share Price - 5Y
B8: Total sales | C8: =IFERROR('Data Sheet'!G17,0) -> 8720.35 | D8: =IFERROR('Data Sheet'!H17,0) -> 10297.83 | E8: =IFERROR('Data Sheet'!I17,0) -> 14442.18 | F8: =IFERROR('Data Sheet'!J17,0) -> 16535.78 | G8: =IFERROR('Data Sheet'!K17,0) -> 18870.35
B9: Sales Growth Y-O-Y | C9: =IFERROR('Profit & Loss'!G4/'Profit & Loss'!F4-1,0) -> -0.047329023 | D9: =IFERROR('Profit & Loss'!H4/'Profit & Loss'!G4-1,0) -> 0.18089641 | E9: =IFERROR('Profit & Loss'!I4/'Profit & Loss'!H4-1,0) -> 0.40244887 | F9: =IFERROR('Profit & Loss'!J4/'Profit & Loss'!I4-1,0) -> 0.14496426 | G9: =IFERROR('Profit & Loss'!K4/'Profit & Loss'!J4-1,0) -> 0.14118294
B10: Gross Profit Margin(%) | C10: =IFERROR('Data Sheet'!G36,0) -> 0.23480021 | D10: =IFERROR('Data Sheet'!H36,0) -> 0.27508223 | E10: =IFERROR('Data Sheet'!I36,0) -> 0.32029652 | F10: =IFERROR('Data Sheet'!J36,0) -> 0.32902833 | G10: =IFERROR('Data Sheet'!K36,0) -> 0.33397473
B11: EBIDTA Margin(%) | C11: =IFERROR('Profit & Loss'!G28,0) -> 0.20449065 | D11: =IFERROR('Profit & Loss'!H28,0) -> 0.21145911 | E11: =IFERROR('Profit & Loss'!I28,0) -> 0.23858725 | F11: =IFERROR('Profit & Loss'!J28,0) -> 0.26181831 | G11: =IFERROR('Profit & Loss'!K28,0) -> 0.25026404
B12: EBIT Margin(%) | C12: =IFERROR('Profit & Loss'!G29,0) -> 0.1528035 | D12: =IFERROR('Profit & Loss'!H29,0) -> 0.16757317 | E12: =IFERROR('Profit & Loss'!I29,0) -> 0.20215161 | F12: =IFERROR('Profit & Loss'!J29,0) -> 0.2256785 | G12: =IFERROR('Profit & Loss'!K29,0) -> 0.21161452
B13: Net Profit Margin (%) | C13: =IFERROR('Profit & Loss'!G12/'Profit & Loss'!G4,0) -> 0.15445366 | D13: =IFERROR('Profit & Loss'!H12/'Profit & Loss'!H4,0) -> 0.162811 | E13: =IFERROR('Profit & Loss'!I12/'Profit & Loss'!I4,0) -> 0.20176594 | F13: =IFERROR('Profit & Loss'!J12/'Profit & Loss'!J4,0) -> 0.24196077 | G13: =IFERROR('Profit & Loss'!K12/'Profit & Loss'!K4,0) -> 0.25089307
B14: Earnig Per Share (In rs) | C14: =IFERROR('Profit & Loss'!G13,0) -> 49.282473 | D14: =IFERROR('Profit & Loss'!H13,0) -> 61.324067 | E14: =IFERROR('Profit & Loss'!I13,0) -> 106.5426 | F14: =IFERROR('Profit & Loss'!J13,0) -> 146.12893 | G14: =IFERROR('Profit & Loss'!K13,0) -> 172.66375
B15: Eps Growth Margin Y-o-Y | C15: =IFERROR('Profit & Loss'!G13/'Profit & Loss'!F13-1,0) -> -0.26350285 | D15: =IFERROR('Profit & Loss'!H13/'Profit & Loss'!G13-1,0) -> 0.24433826 | E15: =IFERROR('Profit & Loss'!I13/'Profit & Loss'!H13-1,0) -> 0.73737002 | F15: =IFERROR('Profit & Loss'!J13/'Profit & Loss'!I13-1,0) -> 0.37155402 | G15: =IFERROR('Profit & Loss'!K13/'Profit & Loss'!J13-1,0) -> 0.18158501
B16: Dividend per Share | C16: =IFERROR('Profit & Loss'!G32,0) -> 17 | D16: =IFERROR('Profit & Loss'!H32,0) -> 21 | E16: =IFERROR('Profit & Loss'!I32,0) -> 37 | F16: =IFERROR('Profit & Loss'!J32,0) -> 51 | G16: =IFERROR('Profit & Loss'!K32,0) -> 70
B17: Divident Growth Margin Y-o-Y | C17: =IFERROR('Profit & Loss'!G33,0) -> 0.36049817 | D17: =IFERROR('Profit & Loss'!H33,0) -> 0.23529412 | E17: =IFERROR('Profit & Loss'!I33,0) -> 0.76190476 | F17: =IFERROR('Profit & Loss'!J33,0) -> 0.37837838 | G17: =IFERROR('Profit & Loss'!K33,0) -> 0.37254902
B19: Key Financial Ratio | C19: 44286 | D19: 44651 | E19: 45016 | F19: 45382 | G19: 45747 | I19: Volume - 5Y
B21: Price to Earnings | C21: =IFERROR('Profit & Loss'!G14,0) -> 52.837242 | D21: =IFERROR('Profit & Loss'!H14,0) -> 40.068282 | E21: =IFERROR('Profit & Loss'!I14,0) -> 27.677662 | F21: =IFERROR('Profit & Loss'!J14,0) -> 27.505163 | G21: =IFERROR('Profit & Loss'!K14,0) -> 30.971759
B22: EV/EBIDTA | C22: =IFERROR('Profit & Loss'!G40,0) -> 36.761855 | D22: =IFERROR('Profit & Loss'!H40,0) -> 29.649435 | E22: =IFERROR('Profit & Loss'!I40,0) -> 23.26767 | F22: =IFERROR('Profit & Loss'!J40,0) -> 25.482129 | G22: =IFERROR('Profit & Loss'!K40,0) -> 31.090922
B23: EV/Sales | C23: =IFERROR('Profit & Loss'!G41,0) -> 7.5174555 | D23: =IFERROR('Profit & Loss'!H41,0) -> 6.2696433 | E23: =IFERROR('Profit & Loss'!I41,0) -> 5.5513695 | F23: =IFERROR('Profit & Loss'!J41,0) -> 6.6716879 | G23: =IFERROR('Profit & Loss'!K41,0) -> 7.7809396
B24: Price to Book | C24: =IFERROR('Profit & Loss'!G42,0) -> 6.2218444 | D24: =IFERROR('Profit & Loss'!H42,0) -> 5.3282425 | E24: =IFERROR('Profit & Loss'!I42,0) -> 5.3802229 | F24: =IFERROR('Profit & Loss'!J42,0) -> 6.0983764 | G24: =IFERROR('Profit & Loss'!K42,0) -> 6.8853569
B25: Retrun on Equity(%) | C25: =IFERROR('Profit & Loss'!G15/'Data Sheet'!G74,0) -> 0.17885979 | D25: =IFERROR('Profit & Loss'!H15/'Data Sheet'!H74,0) -> 0.15224138 | E25: =IFERROR('Profit & Loss'!I15/'Data Sheet'!I74,0) -> 0.15360482 | F25: =IFERROR('Profit & Loss'!J15/'Data Sheet'!J74,0) -> 0.17388178 | G25: =IFERROR('Profit & Loss'!K15/'Data Sheet'!K74,0) -> 0.19679176
B26: Retrun on Capital(%) | C26: =IFERROR('Data Sheet'!G30/('Data Sheet'!G74-'Data Sheet'!G59),0) -> 0.093929576 | D26: =IFERROR('Data Sheet'!H30/('Data Sheet'!H74-'Data Sheet'!H59),0) -> 0.10457756 | E26: =IFERROR('Data Sheet'!I30/('Data Sheet'!I74-'Data Sheet'!I59),0) -> 0.15410146 | F26: =IFERROR('Data Sheet'!J30/('Data Sheet'!J74-'Data Sheet'!J59),0) -> 0.17628942 | G26: =IFERROR('Data Sheet'!K30/('Data Sheet'!K74-'Data Sheet'!K59),0) -> 0.1772118
B28: Top 10 Share Holders | C28: =data!J25 -> No of Shares (in Cr) | D28: =data!K25 -> Shareholding (%) | F28: =data!L25 -> Market value(in Cr) | I28: Share Holding Pattern
B30: =data!I26 -> THE SIMRAN SIDDHARTHA TARA BENEFIT TRUST (Name of trustees are mentioned in Note-4) | C30: =data!J26 -> 12.030648 | D30: =data!K26 -> 0.4386 | G30: =data!L26 -> 96509.858
B31: =data!I27 -> Sbi Nifty 50 Etf | C31: =data!J27 -> 0.8167427 | D31: =data!K27 -> 0.0298 | G31: =data!L27 -> 6551.9099
B32: =data!I28 -> Hdfc Trustee Company Limited-Hdfc Flexi Cap Fund | C32: =data!J28 -> 0.6861231 | D32: =data!K28 -> 0.025 | G32: =data!L28 -> 5504.0795
B33: =data!I29 -> THE BRINDA LAL TRUST (Mrs Anita Lal Mr. Vikram Lal & Mr. Ravi Prakash) | C33: =data!J29 -> 0.485707 | D33: =data!K29 -> 0.0177 | G33: =data!L29 -> 3896.3416
B34: =data!I30 -> New World Fund Inc | C34: =data!J30 -> 0.421887 | D34: =data!K30 -> 0.0154 | G34: =data!L30 -> 3384.3775
B35: =data!I31 -> Uti Nifty 50 Etf | C35: =data!J31 -> 0.3671085 | D35: =data!K31 -> 0.0134 | G35: =data!L31 -> 2944.9444
B36: =data!I32 -> Government Of Singapore | C36: =data!J32 -> 0.3233263 | D36: =data!K32 -> 0.0118 | G36: =data!L32 -> 2593.7236
B37: =data!I33 -> Simran Lal | C37: =data!J33 -> 0.315241 | D37: =data!K33 -> 0.0115 | G37: =data!L33 -> 2528.8633
B38: =data!I34 -> TARA LAL | C38: =data!J34 -> 0.314994 | D38: =data!K34 -> 0.0115 | G38: =data!L34 -> 2526.8819
B39: =data!I35 -> Nps Trust- A/C Sbi Pension Fund Scheme - State Govt | C39: =data!J35 -> 0.3089972 | D39: =data!K35 -> 0.0113 | G39: =data!L35 -> 2478.7755
B41: Mangerial Remuneration | C41: Designation | D41: Remuneration | F41: x of Median Salary | I41: Capital Strucutre
B43: Mr. Siddhartha Lal | C43: CMD | D43: 32.72 | F43: 358.4 | I43: Share Price as 18-02-2026 | L43: 8022
B44: Mr. S Sandilya | C44: CNID | D44: 73.03 | F44: 9.1 | I44: Number of Shares o/s | L44: ='Data Sheet'!B6 -> 27.429924
B45: Mr. Govindarajan Balakrishnan | C45: MD | D45: 19.4 | F45: 211.8 | I45: Market Captialziation | L45: =L43*L44 -> 220042.85
B46: Mr. Atul Sharma | C46: CS | I46: Less: Cash & Equlivant | L46: ='Data Sheet'!K69*-1 -> -263.01
B47: Ms. Vidhya Srinivasan | C47: CFO | I47: Add:Total Debt | L47: ='Data Sheet'!K59 -> 458.13
I48: Entrpise Value | L48: =SUM(L45:L47) -> 220237.97
B50: Recent updates
B52: Eicher Motors Ltd Hits New 52-Week High of Rs.8140 on 19 Feb 2026
...

Sheet Historical IFS
D2: =data!C23 -> Eicher Motors Limited is an Indian multinational automotive company that manufactures motorcycles and commercial vehicles, headquartered in New Delhi. Eicher is the parent company of Royal Enfield, a manufacturer of middleweight motorcycles. It also manufactures Eicher branded trucks and buses, under a joint venture with Volvo Group.
B9: ="Historical Finanical Statement - "&'Balance Sheet'!A1 -> Historical Finanical Statement - EICHER MOTORS LTD
B10: Years | C10: ='Balance Sheet'!B3 -> 42460 | D10: ='Balance Sheet'!C3 -> 42825 | E10: ='Balance Sheet'!D3 -> 43190 | F10: ='Balance Sheet'!E3 -> 43555 | G10: ='Balance Sheet'!F3 -> 43921 | H10: ='Balance Sheet'!G3 -> 44286 | I10: ='Balance Sheet'!H3 -> 44651 | J10: ='Balance Sheet'!I3 -> 45016 | ... L10: ='Balance Sheet'!K3 -> 45747 | M10: LTM
A11: # | B11: Income Statement
B12: Sales | C12: =IFERROR('Profit & Loss'!B4,'Profit & Loss'!B40) -> 6173.46 | D12: =IFERROR('Profit & Loss'!C4,'Profit & Loss'!C40) -> 7033.36 | E12: =IFERROR('Profit & Loss'!D4,'Profit & Loss'!D40) -> 8964.96 | F12: =IFERROR('Profit & Loss'!E4,'Profit & Loss'!E40) -> 9797.06 | G12: =IFERROR('Profit & Loss'!F4,'Profit & Loss'!F40) -> 9153.58 | H12: =IFERROR('Profit & Loss'!G4,'Profit & Loss'!G40) -> 8720.35 | I12: =IFERROR('Profit & Loss'!H4,'Profit & Loss'!H40) -> 10297.83 | J12: =IFERROR('Profit & Loss'!I4,'Profit & Loss'!I40) -> 14442.18 | ... L12: =IFERROR('Profit & Loss'!K4,'Profit & Loss'!K40) -> 18870.35 | M12: =IFERROR(SUM(#REF!),0) -> 0
B13: Sales Growth | C13: - | D13: =IFERROR(D12/C12-1,0) -> 0.1392898 | E13: =IFERROR(E12/D12-1,0) -> 0.27463403 | F13: =IFERROR(F12/E12-1,0) -> 0.092816923 | G13: =IFERROR(G12/F12-1,0) -> -0.065680929 | H13: =IFERROR(H12/G12-1,0) -> -0.047329023 | I13: =IFERROR(I12/H12-1,0) -> 0.18089641 | J13: =IFERROR(J12/I12-1,0) -> 0.40244887 | K13: =IFERROR(K12/J12-1,0) -> 0.14496426 | L13: =IFERROR(L12/K12-1,0) -> 0.14118294 | M13: =M12/L12-1 -> -1
B15: COGS | C15: =IFERROR(SUM('Data Sheet'!B18,'Data Sheet'!B20:B22)-1*'Data Sheet'!B190,0) -> 4067.88 | D15: =IFERROR(SUM('Data Sheet'!C18,'Data Sheet'!C20:C22)-1*'Data Sheet'!C190,0) -> 4371.11 | E15: =IFERROR(SUM('Data Sheet'!D18,'Data Sheet'!D20:D22)-1*'Data Sheet'!D190,0) -> 5515.92 | F15: =IFERROR(SUM('Data Sheet'!E18,'Data Sheet'!E20:E22)-1*'Data Sheet'!E190,0) -> 6302.53 | G15: =IFERROR(SUM('Data Sheet'!F18,'Data Sheet'!F20:F22)-1*'Data Sheet'!F190,0) -> 6029.8 | H15: =IFERROR(SUM('Data Sheet'!G18,'Data Sheet'!G20:G22)-1*'Data Sheet'!G190,0) -> 6466.91 | I15: =IFERROR(SUM('Data Sheet'!H18,'Data Sheet'!H20:H22)-1*'Data Sheet'!H190,0) -> 7316.49 | J15: =IFERROR(SUM('Data Sheet'!I18,'Data Sheet'!I20:I22)-1*'Data Sheet'!I190,0) -> 9753.15 | ... L15: =IFERROR(SUM('Data Sheet'!K18,'Data Sheet'!K20:K22)-1*'Data Sheet'!K190,0) -> 12404.62 | M15: =IFERROR(SUM(#REF!),0) -> 0
B16: COGS % Sales | C16: =C15/C12 -> 0.65893032 | D16: =D15/D12 -> 0.62148248 | E16: =E15/E12 -> 0.61527547 | F16: =F15/F12 -> 0.6433083 | G16: =G15/G12 -> 0.6587368 | H16: =H15/H12 -> 0.74158835 | I16: =I15/I12 -> 0.71048852 | J16: =J15/J12 -> 0.67532395 | ... M16: =M15/M12 -> #DIV/0!
B18: Gross Profit | C18: =C12-C15 -> 2105.58 | D18: =D12-D15 -> 2662.25 | E18: =E12-E15 -> 3449.04 | F18: =F12-F15 -> 3494.53 | G18: =G12-G15 -> 3123.78 | H18: =H12-H15 -> 2253.44 | I18: =I12-I15 -> 2981.34 | J18: =J12-J15 -> 4689.03 | ... M18: =M12-M15 -> 0
B19: Gross Profit Margin | C19: =C18/C12 -> 0.34106968 | D19: =D18/D12 -> 0.37851752 | E19: =E18/E12 -> 0.38472453 | F19: =F18/F12 -> 0.3566917 | G19: =G18/G12 -> 0.3412632 | H19: =H18/H12 -> 0.25841165 | I19: =I18/I12 -> 0.28951148 | J19: =J18/J12 -> 0.32467605 | ... M19: =M18/M12 -> #DIV/0!
B21: Selling & Other Expenses | C21: =IFERROR(SUM('Data Sheet'!B23:B24),0) -> 477.9 | D21: =IFERROR(SUM('Data Sheet'!C23:C24),0) -> 507.55 | E21: =IFERROR(SUM('Data Sheet'!D23:D24),0) -> 674.28 | F21: =IFERROR(SUM('Data Sheet'!E23:E24),0) -> 800.45 | G21: =IFERROR(SUM('Data Sheet'!F23:F24),0) -> 856.8 | H21: =IFERROR(SUM('Data Sheet'!G23:G24),0) -> 676.11 | I21: =IFERROR(SUM('Data Sheet'!H23:H24),0) -> 952.36 | J21: =IFERROR(SUM('Data Sheet'!I23:I24),0) -> 1306.56 | ... L21: =IFERROR(SUM('Data Sheet'!K23:K24),0) -> 1906.67
B22: S&G % of sales | C22: =C21/C12 -> 0.077412019 | D22: =D21/D12 -> 0.072163234 | E22: =E21/E12 -> 0.075212829 | F22: =F21/F12 -> 0.081703082 | G22: =G21/G12 -> 0.093602722 | H22: =H21/H12 -> 0.077532438 | I22: =I21/I12 -> 0.09248162 | J22: =J21/J12 -> 0.090468336 | ... M22: =M21/M12 -> #DIV/0!
B24: EBITDA | C24: =C18-C21 -> 1627.68 | D24: =D18-D21 -> 2154.7 | E24: =E18-E21 -> 2774.76 | F24: =F18-F21 -> 2694.08 | G24: =G18-G21 -> 2266.98 | H24: =H18-H21 -> 1577.33 | I24: =I18-I21 -> 2028.98 | J24: =J18-J21 -> 3382.47 | ... L24: =L18-L21 -> 4559.06 | M24: =IFERROR(SUM('Data Sheet'!H44:K46),0) -> 3010.92
B25: EBITA Margin | C25: =C24/C12 -> 0.26365766 | D25: =D24/D12 -> 0.30635429 | E25: =E24/E12 -> 0.3095117 | F25: =F24/F12 -> 0.27498862 | G25: =G24/G12 -> 0.24766048 | H25: =H24/H12 -> 0.18087921 | I25: =I24/I12 -> 0.19702986 | J25: =J24/J12 -> 0.23420772 | ... M25: =M24/M12 -> #DIV/0!
B27: Intrest | C27: =IFERROR('Data Sheet'!B27,0) -> 2.12 | D27: =IFERROR('Data Sheet'!C27,0) -> 3.56 | E27: =IFERROR('Data Sheet'!D27,0) -> 5.34 | F27: =IFERROR('Data Sheet'!E27,0) -> 7.33 | G27: =IFERROR('Data Sheet'!F27,0) -> 18.88 | H27: =IFERROR('Data Sheet'!G27,0) -> 16.45 | I27: =IFERROR('Data Sheet'!H27,0) -> 18.78 | J27: =IFERROR('Data Sheet'!I27,0) -> 28.02 | ... L27: =IFERROR('Data Sheet'!K27,0) -> 54.34 | M27: =IFERROR(SUM('Data Sheet'!H46:K46),0) -> 62.99
B28: Interst % sales | C28: =C27/C12 -> 0.00034340548 | D28: =D27/D12 -> 0.00050615922 | E28: =E27/E12 -> 0.00059565241 | F28: =F27/F12 -> 0.00074818364 | G28: =G27/G12 -> 0.002062581 | H28: =H27/H12 -> 0.0018863922 | I28: =I27/I12 -> 0.0018236852 | J28: =J27/J12 -> 0.0019401503 | ... M28: =M27/M12 -> #DIV/0!
B30: Depreciation | C30: =IFERROR('Data Sheet'!B26,0) -> 136.6 | D30: =IFERROR('Data Sheet'!C26,0) -> 153.81 | E30: =IFERROR('Data Sheet'!D26,0) -> 223.3 | F30: =IFERROR('Data Sheet'!E26,0) -> 300.28 | G30: =IFERROR('Data Sheet'!F26,0) -> 381.54 | H30: =IFERROR('Data Sheet'!G26,0) -> 450.73 | I30: =IFERROR('Data Sheet'!H26,0) -> 451.93 | J30: =IFERROR('Data Sheet'!I26,0) -> 526.21 | ... L30: =IFERROR('Data Sheet'!K26,0) -> 729.33 | M30: =IFERROR(SUM('Data Sheet'!H45:K45),0) -> 778.26
B31: Depreciation % sales | C31: =C30/C12 -> 0.022126976 | D31: =D30/D12 -> 0.021868637 | E31: =E30/E12 -> 0.024908087 | F31: =F30/F12 -> 0.030650011 | G31: =G30/G12 -> 0.041682052 | H31: =H30/H12 -> 0.051687146 | I31: =I30/I12 -> 0.043885945 | J31: =J30/J12 -> 0.036435635 | ... M31: =M30/M12 -> #DIV/0!
B33: Earnig Before Tax | C33: =IFERROR(C24-SUM(C27:C31),0) -> 1488.9375 | D33: =IFERROR(D24-SUM(D27:D31),0) -> 1997.3076 | E33: =IFERROR(E24-SUM(E27:E31),0) -> 2546.0945 | F33: =IFERROR(F24-SUM(F27:F31),0) -> 2386.4386 | G33: =IFERROR(G24-SUM(G27:G31),0) -> 1866.5163 | H33: =IFERROR(H24-SUM(H27:H31),0) -> 1110.0964 | I33: =IFERROR(I24-SUM(I27:I31),0) -> 1558.2243 | J33: =IFERROR(J24-SUM(J27:J31),0) -> 2828.2016 | ... M33: =IFERROR(M24-SUM(M27:M31),0) -> 0
B34: EBT % sales | C34: =C33/C12 -> 0.24118364 | D34: =D33/D12 -> 0.28397631 | E34: =E33/E12 -> 0.28400512 | F34: =F33/F12 -> 0.24358722 | G34: =G33/G12 -> 0.20391107 | H34: =H33/H12 -> 0.12729953 | I34: =I33/I12 -> 0.15131579 | J34: =J33/J12 -> 0.19582927 | ... M34: =M33/M12 -> #DIV/0!
B36: Tax | C36: =IFERROR('Data Sheet'!B29,0) -> 538.88 | D36: =IFERROR('Data Sheet'!C29,0) -> 720.3 | E36: =IFERROR('Data Sheet'!D29,0) -> 935.93 | F36: =IFERROR('Data Sheet'!E29,0) -> 1077.04 | G36: =IFERROR('Data Sheet'!F29,0) -> 527.45 | H36: =IFERROR('Data Sheet'!G29,0) -> 451.5 | I36: =IFERROR('Data Sheet'!H29,0) -> 525.91 | J36: =IFERROR('Data Sheet'!I29,0) -> 885.69 | ... L36: =IFERROR('Data Sheet'!K29,0) -> 1198.63 | M36: =IFERROR(SUM('Data Sheet'!H48:K48),0) -> 1394.66
B37: effective tax rate | C37: =C36/C24 -> 0.33107245 | D37: =D36/D24 -> 0.33429248 | E37: =E36/E24 -> 0.33730124 | F37: =F36/F24 -> 0.39978026 | G37: =G36/G24 -> 0.23266637 | H37: =H36/H24 -> 0.28624321 | I37: =I36/I24 -> 0.2591992 | J37: =J36/J24 -> 0.26184711 | ... M37: =M36/M24 -> 0.46320062
B39: Net Profit | C39: =IFERROR(C33-C36,0) -> 950.05753 | D39: =IFERROR(D33-D36,0) -> 1277.0076 | E39: =IFERROR(E33-E36,0) -> 1610.1645 | F39: =IFERROR(F33-F36,0) -> 1309.3986 | G39: =IFERROR(G33-G36,0) -> 1339.0663 | H39: =IFERROR(H33-H36,0) -> 658.59643 | I39: =IFERROR(I33-I36,0) -> 1032.3143 | J39: =IFERROR(J33-J36,0) -> 1942.5116 | ... M39: =IFERROR(M33-M36,0) -> -1394.66
B40: Net Margin | C40: =IFERROR(C39/C12,0) -> 0.15389385 | D40: =IFERROR(D39/D12,0) -> 0.18156438 | E40: =IFERROR(E39/E12,0) -> 0.17960643 | F40: =IFERROR(F39/F12,0) -> 0.1336522 | G40: =IFERROR(G39/G12,0) -> 0.1462888 | H40: =IFERROR(H39/H12,0) -> 0.075524082 | I40: =IFERROR(I39/I12,0) -> 0.10024581 | J40: =IFERROR(J39/J12,0) -> 0.13450266 | ... M40: =IFERROR(M39/M12,0) -> 0
B42: No of Equtiy shares | C42: =IFERROR('Data Sheet'!B93,0) -> 27.16 | D42: =IFERROR('Data Sheet'!C93,0) -> 27.21 | E42: =IFERROR('Data Sheet'!D93,0) -> 27.26 | F42: =IFERROR('Data Sheet'!E93,0) -> 27.28 | G42: =IFERROR('Data Sheet'!F93,0) -> 27.31 | H42: =IFERROR('Data Sheet'!G93,0) -> 27.33 | I42: =IFERROR('Data Sheet'!H93,0) -> 27.34 | J42: =IFERROR('Data Sheet'!I93,0) -> 27.35 | ... L42: =IFERROR('Data Sheet'!K93,0) -> 27.42
B44: Earning per Share | C44: =IFERROR(C39/C42,0) -> 34.980027 | D44: =IFERROR(D39/D42,0) -> 46.931556 | E44: =IFERROR(E39/E42,0) -> 59.066929 | F44: =IFERROR(F39/F42,0) -> 47.998482 | G44: =IFERROR(G39/G42,0) -> 49.032086 | H44: =IFERROR(H39/H42,0) -> 24.09793 | I44: =IFERROR(I39/I42,0) -> 37.758387 | J44: =IFERROR(J39/J42,0) -> 71.024191 | ... M44: =IFERROR(M39/M42,0) -> 0
B45: EPS Groth | D45: =IFERROR(D44/C44-1,0) -> 0.34166722 | E45: =IFERROR(E44/D44-1,0) -> 0.258576 | F45: =IFERROR(F44/E44-1,0) -> -0.18738822 | G45: =IFERROR(G44/F44-1,0) -> 0.021534078 | H45: =IFERROR(H44/G44-1,0) -> -0.50852733 | I45: =IFERROR(I44/H44-1,0) -> 0.56687262 | J45: =IFERROR(J44/I44-1,0) -> 0.88101763 | K45: =IFERROR(K44/J44-1,0) -> 0.17389749 | ... M45: =IFERROR(M44/L44-1,0) -> -1
B47: Dividend per Share | C47: =IFERROR('Data Sheet'!B31/'Historical IFS'!C42,0) -> 10 | D47: =IFERROR('Data Sheet'!C31/'Historical IFS'!D42,0) -> 10 | E47: =IFERROR('Data Sheet'!D31/'Historical IFS'!E42,0) -> 11 | F47: =IFERROR('Data Sheet'!E31/'Historical IFS'!F42,0) -> 12.5 | G47: =IFERROR('Data Sheet'!F31/'Historical IFS'!G42,0) -> 12.495423 | H47: =IFERROR('Data Sheet'!G31/'Historical IFS'!H42,0) -> 17 | I47: =IFERROR('Data Sheet'!H31/'Historical IFS'!I42,0) -> 21 | J47: =IFERROR('Data Sheet'!I31/'Historical IFS'!J42,0) -> 37 | ... M47: =IFERROR('Data Sheet'!L31/'Historical IFS'!M42,0) -> 0
B48: dividend payout ratio | C48: =IFERROR(C47/C44,0) -> 0.28587742 | D48: =IFERROR(D47/D44,0) -> 0.21307625 | E48: =IFERROR(E47/E44,0) -> 0.18622942 | F48: =IFERROR(F47/F44,0) -> 0.2604249 | G48: =IFERROR(G47/G44,0) -> 0.25484176 | H48: =IFERROR(H47/H44,0) -> 0.70545478 | I48: =IFERROR(I47/I44,0) -> 0.55616783 | J48: =IFERROR(J47/J44,0) -> 0.52094926 | ... M48: =IFERROR(M47/M44,0) -> 0
B50: Retain Earnings | C50: =IFERROR(IF(C44>C47,1-C48,0),0) -> 0.71412258 | D50: =IFERROR(IF(D44>D47,1-D48,0),0) -> 0.78692375 | E50: =IFERROR(IF(E44>E47,1-E48,0),0) -> 0.81377058 | F50: =IFERROR(IF(F44>F47,1-F48,0),0) -> 0.7395751 | G50: =IFERROR(IF(G44>G47,1-G48,0),0) -> 0.74515824 | H50: =IFERROR(IF(H44>H47,1-H48,0),0) -> 0.29454522 | I50: =IFERROR(IF(I44>I47,1-I48,0),0) -> 0.44383217 | J50: =IFERROR(IF(J44>J47,1-J48,0),0) -> 0.47905074 | ... M50: =IFERROR(IF(M44>M47,1-M48,0),0) -> 0
A52: # | B52: Blancesheet
B53: Equity Share Capital | C53: =IFERROR('Data Sheet'!B57,0) -> 27.16 | D53: =IFERROR('Data Sheet'!C57,0) -> 27.21 | E53: =IFERROR('Data Sheet'!D57,0) -> 27.26 | F53: =IFERROR('Data Sheet'!E57,0) -> 27.28 | G53: =IFERROR('Data Sheet'!F57,0) -> 27.3 | H53: =IFERROR('Data Sheet'!G57,0) -> 27.33 | I53: =IFERROR('Data Sheet'!H57,0) -> 27.34 | J53: =IFERROR('Data Sheet'!I57,0) -> 27.35 | ... M53: =IFERROR('Data Sheet'!L57,0) -> 0
B54: Reserves | C54: =IFERROR('Data Sheet'!B58,0) -> 3625.93 | D54: =IFERROR('Data Sheet'!C58,0) -> 5317.86 | E54: =IFERROR('Data Sheet'!D58,0) -> 7002.81 | F54: =IFERROR('Data Sheet'!E58,0) -> 8891.44 | G54: =IFERROR('Data Sheet'!F58,0) -> 9953.63 | H54: =IFERROR('Data Sheet'!G58,0) -> 11410.75 | I54: =IFERROR('Data Sheet'!H58,0) -> 12580.66 | J54: =IFERROR('Data Sheet'!I58,0) -> 14962.93 | ... M54: =IFERROR('Data Sheet'!L58,0) -> 0
B55: Borrowings | C55: =IFERROR('Data Sheet'!B59,0) -> 22.57 | D55: =IFERROR('Data Sheet'!C59,0) -> 111.85 | E55: =IFERROR('Data Sheet'!D59,0) -> 150.84 | F55: =IFERROR('Data Sheet'!E59,0) -> 186.76 | G55: =IFERROR('Data Sheet'!F59,0) -> 249 | H55: =IFERROR('Data Sheet'!G59,0) -> 219.25 | I55: =IFERROR('Data Sheet'!H59,0) -> 107.71 | J55: =IFERROR('Data Sheet'!I59,0) -> 288.41 | ... M55: =IFERROR('Data Sheet'!L59,0) -> 0
B56: Other Liabilities | C56: =IFERROR('Data Sheet'!B60,0) -> 1263.35 | D56: =IFERROR('Data Sheet'!C60,0) -> 1552.16 | E56: =IFERROR('Data Sheet'!D60,0) -> 2341.32 | F56: =IFERROR('Data Sheet'!E60,0) -> 2281.35 | G56: =IFERROR('Data Sheet'!F60,0) -> 2219.79 | H56: =IFERROR('Data Sheet'!G60,0) -> 2901.28 | I56: =IFERROR('Data Sheet'!H60,0) -> 3424.12 | J56: =IFERROR('Data Sheet'!I60,0) -> 3918.95 | ... M56: =IFERROR('Data Sheet'!L60,0) -> 0
B57: Total Liabilities | C57: =IFERROR('Data Sheet'!B61,0) -> 4939.01 | D57: =IFERROR('Data Sheet'!C61,0) -> 7009.08 | E57: =IFERROR('Data Sheet'!D61,0) -> 9522.23 | F57: =IFERROR('Data Sheet'!E61,0) -> 11386.83 | G57: =IFERROR('Data Sheet'!F61,0) -> 12449.72 | H57: =IFERROR('Data Sheet'!G61,0) -> 14558.61 | I57: =IFERROR('Data Sheet'!H61,0) -> 16139.83 | J57: =IFERROR('Data Sheet'!I61,0) -> 19197.64 | ... M57: =IFERROR('Data Sheet'!L61,0) -> 0
B59: Fix Assest Net Block | C59: =IFERROR('Data Sheet'!B62,0) -> 789.59 | D59: =IFERROR('Data Sheet'!C62,0) -> 872.78 | E59: =IFERROR('Data Sheet'!D62,0) -> 1501.69 | F59: =IFERROR('Data Sheet'!E62,0) -> 1874.58 | G59: =IFERROR('Data Sheet'!F62,0) -> 2377.52 | H59: =IFERROR('Data Sheet'!G62,0) -> 2433.3 | I59: =IFERROR('Data Sheet'!H62,0) -> 2424.28 | J59: =IFERROR('Data Sheet'!I62,0) -> 2689.99 | ... L59: =IFERROR('Data Sheet'!K62,0) -> 3473.47
B60: Capital Work in Progress | C60: =IFERROR('Data Sheet'!B63,0) -> 94.48 | D60: =IFERROR('Data Sheet'!C63,0) -> 373.77 | E60: =IFERROR('Data Sheet'!D63,0) -> 333.21 | F60: =IFERROR('Data Sheet'!E63,0) -> 449.74 | G60: =IFERROR('Data Sheet'!F63,0) -> 312.17 | H60: =IFERROR('Data Sheet'!G63,0) -> 314.29 | I60: =IFERROR('Data Sheet'!H63,0) -> 504.78 | J60: =IFERROR('Data Sheet'!I63,0) -> 472.07 | ... L60: =IFERROR('Data Sheet'!K63,0) -> 491.47 | M60: =IFERROR('Data Sheet'!N63,0) -> 0
B61: Investments | C61: =IFERROR('Data Sheet'!B64,0) -> 3388.24 | D61: =IFERROR('Data Sheet'!C64,0) -> 4987.13 | E61: =IFERROR('Data Sheet'!D64,0) -> 5580.84 | F61: =IFERROR('Data Sheet'!E64,0) -> 4922.52 | G61: =IFERROR('Data Sheet'!F64,0) -> 5748.77 | H61: =IFERROR('Data Sheet'!G64,0) -> 3902.14 | I61: =IFERROR('Data Sheet'!H64,0) -> 7720.58 | J61: =IFERROR('Data Sheet'!I64,0) -> 12320.66 | ... M61: =IFERROR('Data Sheet'!L64,0) -> 0
B62: Other Assets | C62: =IFERROR('Data Sheet'!B65-SUM('Data Sheet'!B67:B69),0) -> 276.5 | D62: =IFERROR('Data Sheet'!C65-SUM('Data Sheet'!C67:C69),0) -> 364.4 | E62: =IFERROR('Data Sheet'!D65-SUM('Data Sheet'!D67:D69),0) -> 431.85 | F62: =IFERROR('Data Sheet'!E65-SUM('Data Sheet'!E67:E69),0) -> 457.03 | G62: =IFERROR('Data Sheet'!F65-SUM('Data Sheet'!F67:F69),0) -> 401.56 | H62: =IFERROR('Data Sheet'!G65-SUM('Data Sheet'!G67:G69),0) -> 1045.76 | I62: =IFERROR('Data Sheet'!H65-SUM('Data Sheet'!H67:H69),0) -> 1333.28 | J62: =IFERROR('Data Sheet'!I65-SUM('Data Sheet'!I67:I69),0) -> 1301.98 | ... L62: =IFERROR('Data Sheet'!K65-SUM('Data Sheet'!K67:K69),0) -> 6042.17 | M62: =IFERROR('Data Sheet'!L65,0) -> 0
...

Sheet Ratio Annalysis
D2: =data!C23 -> Eicher Motors Limited is an Indian multinational automotive company that manufactures motorcycles and commercial vehicles, headquartered in New Delhi. Eicher is the parent company of Royal Enfield, a manufacturer of middleweight motorcycles. It also manufactures Eicher branded trucks and buses, under a joint venture with Volvo Group.
B9: ="Ratio Annalysis - " & 'Data Sheet'!B1 -> Ratio Annalysis - EICHER MOTORS LTD
B10: ='Historical IFS'!B10 -> Years | D10: ='Historical IFS'!D10 -> 42825 | E10: ='Historical IFS'!E10 -> 43190 | F10: ='Historical IFS'!F10 -> 43555 | G10: ='Historical IFS'!G10 -> 43921 | H10: ='Historical IFS'!H10 -> 44286 | I10: ='Historical IFS'!I10 -> 44651 | J10: ='Historical IFS'!J10 -> 45016 | K10: ='Historical IFS'!K10 -> 45382 | L10: ='Historical IFS'!L10 -> 45747 | N10: Mean | O10: Median
B12: Sales Growth | D12: =IFERROR('Historical IFS'!D13,0) -> 0.1392898 | E12: =IFERROR('Historical IFS'!E13,0) -> 0.27463403 | F12: =IFERROR('Historical IFS'!F13,0) -> 0.092816923 | G12: =IFERROR('Historical IFS'!G13,0) -> -0.065680929 | H12: =IFERROR('Historical IFS'!H13,0) -> -0.047329023 | I12: =IFERROR('Historical IFS'!I13,0) -> 0.18089641 | J12: =IFERROR('Historical IFS'!J13,0) -> 0.40244887 | K12: =IFERROR('Historical IFS'!K13,0) -> 0.14496426 | L12: =IFERROR('Historical IFS'!L13,0) -> 0.14118294 | N12: =IFERROR(AVERAGE(D12:L12),0) -> 0.14035814 | O12: =IFERROR(MEDIAN(D12:L12),0) -> 0.14118294
B13: EBIDTA Growth | D13: =IFERROR('Historical IFS'!D24/'Historical IFS'!C24-1,0) -> 0.323786 | E13: =IFERROR('Historical IFS'!E24/'Historical IFS'!D24-1,0) -> 0.28777092 | F13: =IFERROR('Historical IFS'!F24/'Historical IFS'!E24-1,0) -> -0.029076389 | G13: =IFERROR('Historical IFS'!G24/'Historical IFS'!F24-1,0) -> -0.15853278 | H13: =IFERROR('Historical IFS'!H24/'Historical IFS'!G24-1,0) -> -0.3042153 | I13: =IFERROR('Historical IFS'!I24/'Historical IFS'!H24-1,0) -> 0.28633831 | J13: =IFERROR('Historical IFS'!J24/'Historical IFS'!I24-1,0) -> 0.66707902 | K13: =IFERROR('Historical IFS'!K24/'Historical IFS'!J24-1,0) -> 0.22169302 | L13: =IFERROR('Historical IFS'!L24/'Historical IFS'!K24-1,0) -> 0.10326353 | N13: =IFERROR(AVERAGE(D13:L13),0) -> 0.15534515 | O13: =IFERROR(MEDIAN(D13:L13),0) -> 0.22169302
B14: EBIT Growth | D14: =IFERROR('Historical IFS'!D33/'Historical IFS'!C33-1,0) -> 0.34143145 | E14: =IFERROR('Historical IFS'!E33/'Historical IFS'!D33-1,0) -> 0.27476332 | F14: =IFERROR('Historical IFS'!F33/'Historical IFS'!E33-1,0) -> -0.062706194 | G14: =IFERROR('Historical IFS'!G33/'Historical IFS'!F33-1,0) -> -0.21786538 | H14: =IFERROR('Historical IFS'!H33/'Historical IFS'!G33-1,0) -> -0.40525756 | I14: =IFERROR('Historical IFS'!I33/'Historical IFS'!H33-1,0) -> 0.40368373 | J14: =IFERROR('Historical IFS'!J33/'Historical IFS'!I33-1,0) -> 0.81501575 | K14: =IFERROR('Historical IFS'!K33/'Historical IFS'!J33-1,0) -> 0.23181486 | L14: =IFERROR('Historical IFS'!L33/'Historical IFS'!K33-1,0) -> 0.083680449 | N14: =IFERROR(AVERAGE(D14:L14),0) -> 0.16272893 | O14: =IFERROR(MEDIAN(D14:L14),0) -> 0.23181486
B15: Net Profit Growth | D15: =IFERROR('Historical IFS'!D39/'Historical IFS'!C39-1,0) -> 0.34413716 | E15: =IFERROR('Historical IFS'!E39/'Historical IFS'!D39-1,0) -> 0.26088871 | F15: =IFERROR('Historical IFS'!F39/'Historical IFS'!E39-1,0) -> -0.18679203 | G15: =IFERROR('Historical IFS'!G39/'Historical IFS'!F39-1,0) -> 0.022657465 | H15: =IFERROR('Historical IFS'!H39/'Historical IFS'!G39-1,0) -> -0.50816741 | I15: =IFERROR('Historical IFS'!I39/'Historical IFS'!H39-1,0) -> 0.56744593 | J15: =IFERROR('Historical IFS'!J39/'Historical IFS'!I39-1,0) -> 0.88170564 | K15: =IFERROR('Historical IFS'!K39/'Historical IFS'!J39-1,0) -> 0.17518513 | L15: =IFERROR('Historical IFS'!L39/'Historical IFS'!K39-1,0) -> 0.12874816 | N15: =IFERROR(AVERAGE(D15:L15),0) -> 0.18731208 | O15: =IFERROR(MEDIAN(D15:L15),0) -> 0.17518513
B16: Divide Growth | D16: =IFERROR('Historical IFS'!D47/'Historical IFS'!C47-1,0) -> 0 | E16: =IFERROR('Historical IFS'!E47/'Historical IFS'!D47-1,0) -> 0.1 | F16: =IFERROR('Historical IFS'!F47/'Historical IFS'!E47-1,0) -> 0.13636364 | G16: =IFERROR('Historical IFS'!G47/'Historical IFS'!F47-1,0) -> -0.00036616624 | H16: =IFERROR('Historical IFS'!H47/'Historical IFS'!G47-1,0) -> 0.36049817 | I16: =IFERROR('Historical IFS'!I47/'Historical IFS'!H47-1,0) -> 0.23529412 | J16: =IFERROR('Historical IFS'!J47/'Historical IFS'!I47-1,0) -> 0.76190476 | K16: =IFERROR('Historical IFS'!K47/'Historical IFS'!J47-1,0) -> 0.37837838 | L16: =IFERROR('Historical IFS'!L47/'Historical IFS'!K47-1,0) -> 0.37254902 | N16: =IFERROR(AVERAGE(D16:L16),0) -> 0.26051355 | O16: =IFERROR(MEDIAN(D16:L16),0) -> 0.23529412
B18: Gross Margin | D18: =IFERROR('Historical IFS'!C19,0) -> 0.34106968 | E18: =IFERROR('Historical IFS'!D19,0) -> 0.37851752 | F18: =IFERROR('Historical IFS'!E19,0) -> 0.38472453 | G18: =IFERROR('Historical IFS'!F19,0) -> 0.3566917 | H18: =IFERROR('Historical IFS'!G19,0) -> 0.3412632 | I18: =IFERROR('Historical IFS'!H19,0) -> 0.25841165 | J18: =IFERROR('Historical IFS'!I19,0) -> 0.28951148 | K18: =IFERROR('Historical IFS'!J19,0) -> 0.32467605 | L18: =IFERROR('Historical IFS'!K19,0) -> 0.3409437 | N18: =IFERROR(AVERAGE(D18:L18),0) -> 0.33508994 | O18: =IFERROR(MEDIAN(D18:L18),0) -> 0.34106968
B19: EBIDTA Margin | D19: =IFERROR('Historical IFS'!D25,0) -> 0.30635429 | E19: =IFERROR('Historical IFS'!E25,0) -> 0.3095117 | F19: =IFERROR('Historical IFS'!F25,0) -> 0.27498862 | G19: =IFERROR('Historical IFS'!G25,0) -> 0.24766048 | H19: =IFERROR('Historical IFS'!H25,0) -> 0.18087921 | I19: =IFERROR('Historical IFS'!I25,0) -> 0.19702986 | J19: =IFERROR('Historical IFS'!J25,0) -> 0.23420772 | K19: =IFERROR('Historical IFS'!K25,0) -> 0.24990294 | L19: =IFERROR('Historical IFS'!L25,0) -> 0.24159912 | N19: =IFERROR(AVERAGE(D19:L19),0) -> 0.24912599 | O19: =IFERROR(MEDIAN(D19:L19),0) -> 0.24766048
B20: EBIT Margin | D20: =IFERROR(('Historical IFS'!D24-'Historical IFS'!D30)/'Historical IFS'!D12,0) -> 0.28448565 | E20: =IFERROR(('Historical IFS'!E24-'Historical IFS'!E30)/'Historical IFS'!E12,0) -> 0.28460361 | F20: =IFERROR(('Historical IFS'!F24-'Historical IFS'!F30)/'Historical IFS'!F12,0) -> 0.24433861 | G20: =IFERROR(('Historical IFS'!G24-'Historical IFS'!G30)/'Historical IFS'!G12,0) -> 0.20597843 | H20: =IFERROR(('Historical IFS'!H24-'Historical IFS'!H30)/'Historical IFS'!H12,0) -> 0.12919206 | I20: =IFERROR(('Historical IFS'!I24-'Historical IFS'!I30)/'Historical IFS'!I12,0) -> 0.15314391 | J20: =IFERROR(('Historical IFS'!J24-'Historical IFS'!J30)/'Historical IFS'!J12,0) -> 0.19777208 | K20: =IFERROR(('Historical IFS'!K24-'Historical IFS'!K30)/'Historical IFS'!K12,0) -> 0.21376312 | L20: =IFERROR(('Historical IFS'!L24-'Historical IFS'!L30)/'Historical IFS'!L12,0) -> 0.2029496 | N20: =IFERROR(AVERAGE(D20:L20),0) -> 0.21291412 | O20: =IFERROR(MEDIAN(D20:L20),0) -> 0.20597843
B21: EBT Margin | D21: =IFERROR('Historical IFS'!D34,0) -> 0.28397631 | E21: =IFERROR('Historical IFS'!E34,0) -> 0.28400512 | F21: =IFERROR('Historical IFS'!F34,0) -> 0.24358722 | G21: =IFERROR('Historical IFS'!G34,0) -> 0.20391107 | H21: =IFERROR('Historical IFS'!H34,0) -> 0.12729953 | I21: =IFERROR('Historical IFS'!I34,0) -> 0.15131579 | J21: =IFERROR('Historical IFS'!J34,0) -> 0.19582927 | K21: =IFERROR('Historical IFS'!K34,0) -> 0.21068379 | L21: =IFERROR('Historical IFS'!L34,0) -> 0.20006775 | N21: =IFERROR(AVERAGE(D21:L21),0) -> 0.2111862 | O21: =IFERROR(MEDIAN(D21:L21),0) -> 0.20391107
B22: Net Profit Margin | D22: =IFERROR('Historical IFS'!D40,0) -> 0.18156438 | E22: =IFERROR('Historical IFS'!E40,0) -> 0.17960643 | F22: =IFERROR('Historical IFS'!F40,0) -> 0.1336522 | G22: =IFERROR('Historical IFS'!G40,0) -> 0.1462888 | H22: =IFERROR('Historical IFS'!H40,0) -> 0.075524082 | I22: =IFERROR('Historical IFS'!I40,0) -> 0.10024581 | J22: =IFERROR('Historical IFS'!J40,0) -> 0.13450266 | K22: =IFERROR('Historical IFS'!K40,0) -> 0.1380528 | L22: =IFERROR('Historical IFS'!L40,0) -> 0.13654853 | N22: =IFERROR(AVERAGE(D22:L22),0) -> 0.13622063 | O22: =IFERROR(MEDIAN(D22:L22),0) -> 0.13654853
B24: Sales Expnens % Sales | D24: =IFERROR('Historical IFS'!D22,0) -> 0.072163234 | E24: =IFERROR('Historical IFS'!E22,0) -> 0.075212829 | F24: =IFERROR('Historical IFS'!F22,0) -> 0.081703082 | G24: =IFERROR('Historical IFS'!G22,0) -> 0.093602722 | H24: =IFERROR('Historical IFS'!H22,0) -> 0.077532438 | I24: =IFERROR('Historical IFS'!I22,0) -> 0.09248162 | J24: =IFERROR('Historical IFS'!J22,0) -> 0.090468336 | K24: =IFERROR('Historical IFS'!K22,0) -> 0.091040761 | L24: =IFERROR('Historical IFS'!L22,0) -> 0.10104052 | N24: =IFERROR(AVERAGE(D24:L24),0) -> 0.086138394 | O24: =IFERROR(MEDIAN(D24:L24),0) -> 0.090468336
B25: Depn % sales | D25: =IFERROR('Historical IFS'!D31,0) -> 0.021868637 | E25: =IFERROR('Historical IFS'!E31,0) -> 0.024908087 | F25: =IFERROR('Historical IFS'!F31,0) -> 0.030650011 | G25: =IFERROR('Historical IFS'!G31,0) -> 0.041682052 | H25: =IFERROR('Historical IFS'!H31,0) -> 0.051687146 | I25: =IFERROR('Historical IFS'!I31,0) -> 0.043885945 | J25: =IFERROR('Historical IFS'!J31,0) -> 0.036435635 | K25: =IFERROR('Historical IFS'!K31,0) -> 0.036139813 | L25: =IFERROR('Historical IFS'!L31,0) -> 0.038649522 | N25: =IFERROR(AVERAGE(D25:L25),0) -> 0.036211872 | O25: =IFERROR(MEDIAN(D25:L25),0) -> 0.036435635
B26: Operting Income % Sales | D26: =D20 -> 0.28448565 | E26: =E20 -> 0.28460361 | F26: =F20 -> 0.24433861 | G26: =G20 -> 0.20597843 | H26: =H20 -> 0.12919206 | I26: =I20 -> 0.15314391 | J26: =J20 -> 0.19777208 | K26: =K20 -> 0.21376312 | L26: =L20 -> 0.2029496 | N26: =IFERROR(AVERAGE(D26:L26),0) -> 0.21291412 | O26: =IFERROR(MEDIAN(D26:L26),0) -> 0.20597843
N27: =IFERROR(AVERAGE(D27:L27),0) -> 0 | O27: =IFERROR(MEDIAN(D27:L27),0) -> 0
B28: Retrun on Capital Employed | D28: =IFERROR(('Historical IFS'!D24-'Historical IFS'!D30)/SUM('Historical IFS'!D53:D54),0) -> 0.37434309 | E28: =IFERROR(('Historical IFS'!E24-'Historical IFS'!E30)/SUM('Historical IFS'!E53:E54),0) -> 0.36293522 | F28: =IFERROR(('Historical IFS'!F24-'Historical IFS'!F30)/SUM('Historical IFS'!F53:F54),0) -> 0.26840174 | G28: =IFERROR(('Historical IFS'!G24-'Historical IFS'!G30)/SUM('Historical IFS'!G53:G54),0) -> 0.18890424 | H28: =IFERROR(('Historical IFS'!H24-'Historical IFS'!H30)/SUM('Historical IFS'!H53:H54),0) -> 0.098495552 | I28: =IFERROR(('Historical IFS'!I24-'Historical IFS'!I30)/SUM('Historical IFS'!I53:I54),0) -> 0.12508328 | J28: =IFERROR(('Historical IFS'!J24-'Historical IFS'!J30)/SUM('Historical IFS'!J53:J54),0) -> 0.1905408 | K28: =IFERROR(('Historical IFS'!K24-'Historical IFS'!K30)/SUM('Historical IFS'!K53:K54),0) -> 0.19587898 | L28: =IFERROR(('Historical IFS'!L24-'Historical IFS'!L30)/SUM('Historical IFS'!L53:L54),0) -> 0.17982916 | N28: =IFERROR(AVERAGE(D28:L28),0) -> 0.22049023 | O28: =IFERROR(MEDIAN(D28:L28),0) -> 0.1905408
B29: Retained Earnigns% | D29: =IFERROR('Historical IFS'!D50,0) -> 0.78692375 | E29: =IFERROR('Historical IFS'!E50,0) -> 0.81377058 | F29: =IFERROR('Historical IFS'!F50,0) -> 0.7395751 | G29: =IFERROR('Historical IFS'!G50,0) -> 0.74515824 | H29: =IFERROR('Historical IFS'!H50,0) -> 0.29454522 | I29: =IFERROR('Historical IFS'!I50,0) -> 0.44383217 | J29: =IFERROR('Historical IFS'!J50,0) -> 0.47905074 | K29: =IFERROR('Historical IFS'!K50,0) -> 0.38830673 | L29: =IFERROR('Historical IFS'!L50,0) -> 0.25509906 | N29: =IFERROR(AVERAGE(D29:L29),0) -> 0.54958462 | O29: =IFERROR(MEDIAN(D29:L29),0) -> 0.47905074
B30: Retrun on Equity% | D30: =IFERROR('Historical IFS'!D39/SUM('Historical IFS'!D53:D54),0) -> 0.23891317 | E30: =IFERROR('Historical IFS'!E39/SUM('Historical IFS'!E53:E54),0) -> 0.22903961 | F30: =IFERROR('Historical IFS'!F39/SUM('Historical IFS'!F53:F54),0) -> 0.14681463 | G30: =IFERROR('Historical IFS'!G39/SUM('Historical IFS'!G53:G54),0) -> 0.13416247 | H30: =IFERROR('Historical IFS'!H39/SUM('Historical IFS'!H53:H54),0) -> 0.057579281 | I30: =IFERROR('Historical IFS'!I39/SUM('Historical IFS'!I53:I54),0) -> 0.08187772 | J30: =IFERROR('Historical IFS'!J39/SUM('Historical IFS'!J53:J54),0) -> 0.12958475 | K30: =IFERROR('Historical IFS'!K39/SUM('Historical IFS'!K53:K54),0) -> 0.12650284 | L30: =IFERROR('Historical IFS'!L39/SUM('Historical IFS'!L53:L54),0) -> 0.12099264 | N30: =IFERROR(AVERAGE(D30:L30),0) -> 0.14060746 | O30: =IFERROR(MEDIAN(D30:L30),0) -> 0.12958475
B31: Self Sustained Growth Rate | D31: =IFERROR(D29*D30,0) -> 0.18800645 | E31: =IFERROR(E29*E30,0) -> 0.1863857 | F31: =IFERROR(F29*F30,0) -> 0.10858045 | G31: =IFERROR(G29*G30,0) -> 0.099972273 | H31: =IFERROR(H29*H30,0) -> 0.016959702 | I31: =IFERROR(I29*I30,0) -> 0.036339966 | J31: =IFERROR(J29*J30,0) -> 0.062077668 | K31: =IFERROR(K29*K30,0) -> 0.049121903 | L31: =IFERROR(L29*L30,0) -> 0.030865108 | N31: =IFERROR(AVERAGE(D31:L31),0) -> 0.086478801 | O31: =IFERROR(MEDIAN(D31:L31),0) -> 0.062077668
B32: Interest Coverage Ratio | D32: =IFERROR(('Historical IFS'!D24-'Historical IFS'!D30)/'Historical IFS'!D27,0) -> 562.04775 | E32: =IFERROR(('Historical IFS'!E24-'Historical IFS'!E30)/'Historical IFS'!E27,0) -> 477.8015 | F32: =IFERROR(('Historical IFS'!F24-'Historical IFS'!F30)/'Historical IFS'!F27,0) -> 326.57572 | G32: =IFERROR(('Historical IFS'!G24-'Historical IFS'!G30)/'Historical IFS'!G27,0) -> 99.864407 | H32: =IFERROR(('Historical IFS'!H24-'Historical IFS'!H30)/'Historical IFS'!H27,0) -> 68.486322 | I32: =IFERROR(('Historical IFS'!I24-'Historical IFS'!I30)/'Historical IFS'!I27,0) -> 83.974973 | J32: =IFERROR(('Historical IFS'!J24-'Historical IFS'!J30)/'Historical IFS'!J27,0) -> 101.93647 | K32: =IFERROR(('Historical IFS'!K24-'Historical IFS'!K30)/'Historical IFS'!K27,0) -> 69.472091 | L32: =IFERROR(('Historical IFS'!L24-'Historical IFS'!L30)/'Historical IFS'!L27,0) -> 70.477181 | N32: =IFERROR(AVERAGE(D32:L32),0) -> 206.73738 | O32: =IFERROR(MEDIAN(D32:L32),0) -> 99.864407
B34: Debtor Turnover Ratio | D34: =IFERROR('Historical IFS'!D12/'Historical IFS'!D77,0) -> -413.72706 | E34: =IFERROR('Historical IFS'!E12/'Historical IFS'!E77,0) -> -498.05333 | F34: =IFERROR('Historical IFS'!F12/'Historical IFS'!F77,0) -> -544.28111 | G34: =IFERROR('Historical IFS'!G12/'Historical IFS'!G77,0) -> 0 | H34: =IFERROR('Historical IFS'!H12/'Historical IFS'!H77,0) -> -119.45685 | I34: =IFERROR('Historical IFS'!I12/'Historical IFS'!I77,0) -> -70.053265 | J34: =IFERROR('Historical IFS'!J12/'Historical IFS'!J77,0) -> -244.78271 | K34: =IFERROR('Historical IFS'!K12/'Historical IFS'!K77,0) -> -3307.156 | L34: =IFERROR('Historical IFS'!L12/'Historical IFS'!L77,0) -> -107.2179 | N34: =IFERROR(AVERAGE(D34:L34),0) -> -589.41425 | O34: =IFERROR(MEDIAN(D34:L34),0) -> -244.78271
B35: Creditor Turnover Ratio | D35: ='Historical IFS'!D12/'Historical IFS'!D56 -> 4.531337 | E35: ='Historical IFS'!E12/'Historical IFS'!E56 -> 3.8290195 | F35: ='Historical IFS'!F12/'Historical IFS'!F56 -> 4.2944134 | G35: ='Historical IFS'!G12/'Historical IFS'!G56 -> 4.1236243 | H35: ='Historical IFS'!H12/'Historical IFS'!H56 -> 3.0056906 | I35: ='Historical IFS'!I12/'Historical IFS'!I56 -> 3.0074384 | J35: ='Historical IFS'!J12/'Historical IFS'!J56 -> 3.6852167 | K35: ='Historical IFS'!K12/'Historical IFS'!K56 -> 3.5559594 | L35: ='Historical IFS'!L12/'Historical IFS'!L56 -> 3.4817493 | N35: =IFERROR(AVERAGE(D35:L35),0) -> 3.7238276 | O35: =IFERROR(MEDIAN(D35:L35),0) -> 3.6852167
B36: Invenotry Turn over Ratio | D36: ='Historical IFS'!D12/'Historical IFS'!D66 -> 20.938851 | E36: ='Historical IFS'!E12/'Historical IFS'!E66 -> 22.716805 | F36: ='Historical IFS'!F12/'Historical IFS'!F66 -> 15.467902 | G36: ='Historical IFS'!G12/'Historical IFS'!G66 -> 15.992976 | H36: ='Historical IFS'!H12/'Historical IFS'!H66 -> 9.9706723 | I36: ='Historical IFS'!I12/'Historical IFS'!I66 -> 9.0938096 | J36: ='Historical IFS'!J12/'Historical IFS'!J66 -> 11.296721 | K36: ='Historical IFS'!K12/'Historical IFS'!K66 -> 11.730499 | L36: ='Historical IFS'!L12/'Historical IFS'!L66 -> 12.06737 | N36: =IFERROR(AVERAGE(D36:L36),0) -> 14.363956 | O36: =IFERROR(MEDIAN(D36:L36),0) -> 12.06737
B37: Fixed Assest Turnover Ratio | D37: ='Historical IFS'!D12/'Historical IFS'!D59 -> 8.0585715 | E37: ='Historical IFS'!E12/'Historical IFS'!E59 -> 5.9699139 | F37: ='Historical IFS'!F12/'Historical IFS'!F59 -> 5.2262694 | G37: ='Historical IFS'!G12/'Historical IFS'!G59 -> 3.8500538 | H37: ='Historical IFS'!H12/'Historical IFS'!H59 -> 3.5837546 | I37: ='Historical IFS'!I12/'Historical IFS'!I59 -> 4.247789 | J37: ='Historical IFS'!J12/'Historical IFS'!J59 -> 5.3688601 | K37: ='Historical IFS'!K12/'Historical IFS'!K59 -> 5.6738586 | L37: ='Historical IFS'!L12/'Historical IFS'!L59 -> 5.4327085 | N37: =IFERROR(AVERAGE(D37:L37),0) -> 5.2679755 | O37: =IFERROR(MEDIAN(D37:L37),0) -> 5.3688601
B38: Capitla turn over ratio | D38: =IFERROR('Historical IFS'!D12/SUM('Historical IFS'!D53:D54),0) -> 1.3158593 | E38: =IFERROR('Historical IFS'!E12/SUM('Historical IFS'!E53:E54),0) -> 1.2752305 | F38: =IFERROR('Historical IFS'!F12/SUM('Historical IFS'!F53:F54),0) -> 1.0984827 | G38: =IFERROR('Historical IFS'!G12/SUM('Historical IFS'!G53:G54),0) -> 0.91710692 | H38: =IFERROR('Historical IFS'!H12/SUM('Historical IFS'!H53:H54),0) -> 0.76239631 | I38: =IFERROR('Historical IFS'!I12/SUM('Historical IFS'!I53:I54),0) -> 0.81676951 | J38: =IFERROR('Historical IFS'!J12/SUM('Historical IFS'!J53:J54),0) -> 0.96343631 | K38: =IFERROR('Historical IFS'!K12/SUM('Historical IFS'!K53:K54),0) -> 0.91633662 | L38: =IFERROR('Historical IFS'!L12/SUM('Historical IFS'!L53:L54),0) -> 0.88607794 | N38: =IFERROR(AVERAGE(D38:L38),0) -> 0.99463291 | O38: =IFERROR(MEDIAN(D38:L38),0) -> 0.91710692
B41: (In days)
B42: debtor days | D42: =IFERROR(365/D34,0) -> -0.88222414 | E42: =IFERROR(365/E34,0) -> -0.73285324 | F42: =IFERROR(365/F34,0) -> -0.67060935 | G42: =IFERROR(365/G34,0) -> 0 | H42: =IFERROR(365/H34,0) -> -3.0554966 | I42: =IFERROR(365/I34,0) -> -5.210321 | J42: =IFERROR(365/J34,0) -> -1.4911184 | K42: =IFERROR(365/K34,0) -> -0.11036673 | L42: =IFERROR(365/L34,0) -> -3.4042824 | N42: =IFERROR(AVERAGE(D42:L42),0) -> -1.7285858 | O42: =IFERROR(MEDIAN(D42:L42),0) -> -0.88222414
B43: paybales day | D43: =IFERROR(365/D35,0) -> 80.550178 | E43: =IFERROR(365/E35,0) -> 95.324664 | F43: =IFERROR(365/F35,0) -> 84.994146 | G43: =IFERROR(365/G35,0) -> 88.514368 | H43: =IFERROR(365/H35,0) -> 121.43632 | I43: =IFERROR(365/I35,0) -> 121.36574 | J43: =IFERROR(365/J35,0) -> 99.044379 | K43: =IFERROR(365/K35,0) -> 102.64459 | L43: =IFERROR(365/L35,0) -> 104.83236 | N43: =IFERROR(AVERAGE(D43:L43),0) -> 99.856306 | O43: =IFERROR(MEDIAN(D43:L43),0) -> 99.044379
B44: inveontry day | D44: =IFERROR(365/D36,0) -> 17.431711 | E44: =IFERROR(365/E36,0) -> 16.0674 | F44: =IFERROR(365/F36,0) -> 23.597253 | G44: =IFERROR(365/G36,0) -> 22.822519 | H44: =IFERROR(365/H36,0) -> 36.607361 | I44: =IFERROR(365/I36,0) -> 40.137194 | J44: =IFERROR(365/J36,0) -> 32.310261 | K44: =IFERROR(365/K36,0) -> 31.115472 | L44: =IFERROR(365/L36,0) -> 30.246856 | N44: =IFERROR(AVERAGE(D44:L44),0) -> 27.815114 | O44: =IFERROR(MEDIAN(D44:L44),0) -> 30.246856
B45: cash converstion cycle | D45: =SUM(D42,D44)-D43 -> -64.000691 | E45: =SUM(E42,E44)-E43 -> -79.990117 | F45: =SUM(F42,F44)-F43 -> -62.067503 | G45: =SUM(G42,G44)-G43 -> -65.69185 | H45: =SUM(H42,H44)-H43 -> -87.884454 | I45: =SUM(I42,I44)-I43 -> -86.438871 | J45: =SUM(J42,J44)-J43 -> -68.225237 | K45: =SUM(K42,K44)-K43 -> -71.639487 | L45: =SUM(L42,L44)-L43 -> -77.989788 | N45: =IFERROR(AVERAGE(D45:L45),0) -> -73.769778 | O45: =IFERROR(MEDIAN(D45:L45),0) -> -71.639487
B47: CFO/sales | D47: =IFERROR('Historical IFS'!D84/'Historical IFS'!D12,0) -> 0.26587577 | E47: =IFERROR('Historical IFS'!E84/'Historical IFS'!E12,0) -> 0.3258241 | F47: =IFERROR('Historical IFS'!F84/'Historical IFS'!F12,0) -> 0.11411587 | G47: =IFERROR('Historical IFS'!G84/'Historical IFS'!G12,0) -> 0.19445944 | H47: =IFERROR('Historical IFS'!H84/'Historical IFS'!H12,0) -> 0.22074802 | I47: =IFERROR('Historical IFS'!I84/'Historical IFS'!I12,0) -> 0.13546543 | J47: =IFERROR('Historical IFS'!J84/'Historical IFS'!J12,0) -> 0.20003905 | K47: =IFERROR('Historical IFS'!K84/'Historical IFS'!K12,0) -> 0.24867288 | L47: =IFERROR('Historical IFS'!L84/'Historical IFS'!L12,0) -> 0.22209445 | N47: =IFERROR(AVERAGE(D47:L47),0) -> 0.21414389 | O47: =IFERROR(MEDIAN(D47:L47),0) -> 0.22074802
B48: CFO/Total Assest | D48: =IFERROR('Historical IFS'!D84/'Historical IFS'!D70,0) -> 0.26679678 | E48: =IFERROR('Historical IFS'!E84/'Historical IFS'!E70,0) -> 0.30675588 | F48: =IFERROR('Historical IFS'!F84/'Historical IFS'!F70,0) -> 0.098183603 | G48: =IFERROR('Historical IFS'!G84/'Historical IFS'!G70,0) -> 0.1429751 | H48: =IFERROR('Historical IFS'!H84/'Historical IFS'!H70,0) -> 0.13222416 | I48: =IFERROR('Historical IFS'!I84/'Historical IFS'!I70,0) -> 0.086432137 | J48: =IFERROR('Historical IFS'!J84/'Historical IFS'!J70,0) -> 0.15048725 | K48: =IFERROR('Historical IFS'!K84/'Historical IFS'!K70,0) -> 0.17789214 | L48: =IFERROR('Historical IFS'!L84/'Historical IFS'!L70,0) -> 0.15422598 | N48: =IFERROR(AVERAGE(D48:L48),0) -> 0.16844145 | O48: =IFERROR(MEDIAN(D48:L48),0) -> 0.15048725
B49: CFO/Total debt | D49: ='Historical IFS'!D95/'Historical IFS'!D55 -> -15.583371 | E49: ='Historical IFS'!E95/'Historical IFS'!E55 -> -14.207107 | F49: ='Historical IFS'!F95/'Historical IFS'!F55 -> -3.5339473 | G49: ='Historical IFS'!G95/'Historical IFS'!G55 -> -6.060241 | H49: ='Historical IFS'!H95/'Historical IFS'!H55 -> -7.4116306 | I49: ='Historical IFS'!I95/'Historical IFS'!I55 -> -9.135642 | J49: ='Historical IFS'!J95/'Historical IFS'!J55 -> -8.3076176 | K49: ='Historical IFS'!K95/'Historical IFS'!K55 -> -6.759012 | L49: ='Historical IFS'!L95/'Historical IFS'!L55 -> -5.3696549 | N49: =IFERROR(AVERAGE(D49:L49),0) -> -8.4853581 | O49: =IFERROR(MEDIAN(D49:L49),0) -> -7.4116306

Sheet Revenue Forcasting 
D2: =data!C23 -> Eicher Motors Limited is an Indian multinational automotive company that manufactures motorcycles and commercial vehicles, headquartered in New Delhi. Eicher is the parent company of Royal Enfield, a manufacturer of middleweight motorcycles. It also manufactures Eicher branded trucks and buses, under a joint venture with Volvo Group.
B9: ="Revenue Forcasting Sales - " &'Data Sheet'!B1 -> Revenue Forcasting Sales - EICHER MOTORS LTD
B11: year weight | C11: Years | D11: Sales | E11: Sales Growt
B12: 1 | C12: =IFERROR('Data Sheet'!B16,0) -> 42460 | D12: {=TRANSPOSE('Data Sheet'!B17:K17)} -> 6173.46
B13: 2 | C13: =C12+365 -> 42825 | D13: 7033.36 | E13: =D13/D12-1 -> 0.1392898
B14: 3 | C14: =C13+365 -> 43190 | D14: 8964.96 | E14: =D14/D13-1 -> 0.27463403
B15: 4 | C15: =C14+365 -> 43555 | D15: 9797.06 | E15: =D15/D14-1 -> 0.092816923
B16: 5 | C16: =C15+365 -> 43920 | D16: 9153.58 | E16: =D16/D15-1 -> -0.065680929
B17: 6 | C17: =C16+365 -> 44285 | D17: 8720.35 | E17: =D17/D16-1 -> -0.047329023
B18: 7 | C18: =C17+365 -> 44650 | D18: 10297.83 | E18: =D18/D17-1 -> 0.18089641
B19: 8 | C19: =C18+365 -> 45015 | D19: 14442.18 | E19: =D19/D18-1 -> 0.40244887
B20: 9 | C20: =C19+365 -> 45380 | D20: 16535.78 | E20: =D20/D19-1 -> 0.14496426
B21: 10 | C21: =C20+365 -> 45745 | D21: 18870.35 | E21: =D21/D20-1 -> 0.14118294
B22: 11 | C22: =C21+365 -> 46110 | D22: =FORECAST(B22,$D$12:$D$21,$B$12:$B$21) -> 17973.695 | E22: =D22/D21-1 -> -0.047516589
B23: 12 | C23: =C22+365 -> 46475 | D23: =FORECAST(B23,$D$12:$D$21,$B$12:$B$21) -> 19241.842 | E23: =D23/D22-1 -> 0.070555677
B24: 13 | C24: =C23+365 -> 46840 | D24: =FORECAST(B24,$D$12:$D$21,$B$12:$B$21) -> 20509.988 | E24: =D24/D23-1 -> 0.065905659
B25: 14 | C25: =C24+365 -> 47205 | D25: =FORECAST(B25,$D$12:$D$21,$B$12:$B$21) -> 21778.134 | E25: =D25/D24-1 -> 0.061830668
B26: 15 | C26: =C25+365 -> 47570 | D26: =FORECAST(B26,$D$12:$D$21,$B$12:$B$21) -> 23046.28 | E26: =D26/D25-1 -> 0.058230252
B27: 16 | C27: =C26+365 -> 47935 | D27: =FORECAST(B27,$D$12:$D$21,$B$12:$B$21) -> 24314.427 | E27: =D27/D26-1 -> 0.05502607
B29: ="EBITA - "&'Data Sheet'!B1 -> EBITA - EICHER MOTORS LTD
B31: year weight | C31: Years | D31: Sales | E31: Sales Growt
B32: 1 | C32: =IFERROR('Data Sheet'!B16,0) -> 42460 | D32: {=TRANSPOSE('Historical IFS'!C24:M24)} -> 1627.68
B33: 2 | C33: =C32+365 -> 42825 | D33: 2154.7 | E33: =D33/D32-1 -> 0.323786
B34: 3 | C34: =C33+365 -> 43190 | D34: 2774.76 | E34: =D34/D33-1 -> 0.28777092
B35: 4 | C35: =C34+365 -> 43555 | D35: 2694.08 | E35: =D35/D34-1 -> -0.029076389
B36: 5 | C36: =C35+365 -> 43920 | D36: 2266.98 | E36: =D36/D35-1 -> -0.15853278
B37: 6 | C37: =C36+365 -> 44285 | D37: 1577.33 | E37: =D37/D36-1 -> -0.3042153
B38: 7 | C38: =C37+365 -> 44650 | D38: 2028.98 | E38: =D38/D37-1 -> 0.28633831
B39: 8 | C39: =C38+365 -> 45015 | D39: 3382.47 | E39: =D39/D38-1 -> 0.66707902
B40: 9 | C40: =C39+365 -> 45380 | D40: 4132.34 | E40: =D40/D39-1 -> 0.22169302
B41: 10 | C41: =C40+365 -> 45745 | D41: 4559.06 | E41: =D41/D40-1 -> 0.10326353
B42: 11 | C42: =C41+365 -> 46110 | D42: =FORECAST(B42,D32:D41,B32:B41) -> 4072.488 | E42: =D42/D41-1 -> -0.10672639
B43: 12 | C43: =C42+365 -> 46475 | D43: =FORECAST(B43,D33:D42,B33:B42) -> 4322.3059 | E43: =D43/D42-1 -> 0.061342812
B44: 13 | C44: =C43+365 -> 46840 | D44: =FORECAST(B44,D34:D43,B34:B43) -> 4649.6023 | E44: =D44/D43-1 -> 0.075722656
B45: 14 | C45: =C44+365 -> 47205 | D45: =FORECAST(B45,D35:D44,B35:B44) -> 5128.6597 | E45: =D45/D44-1 -> 0.1030319
B46: 15 | C46: =C45+365 -> 47570 | D46: =FORECAST(B46,D36:D45,B36:B45) -> 5652.8358 | E46: =D46/D45-1 -> 0.10220529
B47: 16 | C47: =C46+365 -> 47935 | D47: =FORECAST(B47,D37:D46,B37:B46) -> 6110.4838 | E47: =D47/D46-1 -> 0.080959
B50: ="EPS - "&'Data Sheet'!B1 -> EPS - EICHER MOTORS LTD
B52: year weight | C52: Years | D52: Sales | E52: Sales Growt
B53: 1 | C53: =IFERROR('Data Sheet'!B16,0) -> 42460 | D53: {=TRANSPOSE('Historical IFS'!C44:M44)} -> 34.980027
...

Sheet Common size statement
D2: =data!C23 -> Eicher Motors Limited is an Indian multinational automotive company that manufactures motorcycles and commercial vehicles, headquartered in New Delhi. Eicher is the parent company of Royal Enfield, a manufacturer of middleweight motorcycles. It also manufactures Eicher branded trucks and buses, under a joint venture with Volvo Group.
B9: ="Common size Income statement - "&'Data Sheet'!B1 -> Common size Income statement - EICHER MOTORS LTD
B11: Particulars | C11: =IFERROR('Data Sheet'!B16,0) -> 42460 | D11: =IFERROR('Data Sheet'!C16,0) -> 42825 | E11: =IFERROR('Data Sheet'!D16,0) -> 43190 | F11: =IFERROR('Data Sheet'!E16,0) -> 43555 | G11: =IFERROR('Data Sheet'!F16,0) -> 43921 | H11: =IFERROR('Data Sheet'!G16,0) -> 44286 | I11: =IFERROR('Data Sheet'!H16,0) -> 44651 | J11: =IFERROR('Data Sheet'!I16,0) -> 45016 | ... L11: =IFERROR('Data Sheet'!K16,0) -> 45747
B12: =IFERROR('Data Sheet'!A17,0) -> Sales | C12: ='Data Sheet'!B17/'Data Sheet'!B$17 -> 1 | D12: ='Data Sheet'!C17/'Data Sheet'!C$17 -> 1 | E12: ='Data Sheet'!D17/'Data Sheet'!D$17 -> 1 | F12: ='Data Sheet'!E17/'Data Sheet'!E$17 -> 1 | G12: ='Data Sheet'!F17/'Data Sheet'!F$17 -> 1 | H12: ='Data Sheet'!G17/'Data Sheet'!G$17 -> 1 | I12: ='Data Sheet'!H17/'Data Sheet'!H$17 -> 1 | J12: ='Data Sheet'!I17/'Data Sheet'!I$17 -> 1 | ... L12: ='Data Sheet'!K17/'Data Sheet'!K$17 -> 1
B13: =IFERROR('Data Sheet'!A18,0) -> Raw Material Cost | C13: ='Data Sheet'!B18/'Data Sheet'!B$17 -> 0.56657531 | D13: ='Data Sheet'!C18/'Data Sheet'!C$17 -> 0.52972121 | E13: ='Data Sheet'!D18/'Data Sheet'!D$17 -> 0.52192871 | F13: ='Data Sheet'!E18/'Data Sheet'!E$17 -> 0.53787973 | G13: ='Data Sheet'!F18/'Data Sheet'!F$17 -> 0.5369025 | H13: ='Data Sheet'!G18/'Data Sheet'!G$17 -> 0.61005006 | I13: ='Data Sheet'!H18/'Data Sheet'!H$17 -> 0.59306475 | J13: ='Data Sheet'!I18/'Data Sheet'!I$17 -> 0.57339266 | ... L13: ='Data Sheet'!K18/'Data Sheet'!K$17 -> 0.55484344
B14: =IFERROR('Data Sheet'!A19,0) -> Change in Inventory | C14: ='Data Sheet'!B19/'Data Sheet'!B$17 -> 0.01005109 | D14: ='Data Sheet'!C19/'Data Sheet'!C$17 -> 0.0027881411 | E14: ='Data Sheet'!D19/'Data Sheet'!D$17 -> 0.0037780425 | F14: ='Data Sheet'!E19/'Data Sheet'!E$17 -> 0.021451333 | G14: ='Data Sheet'!F19/'Data Sheet'!F$17 -> -0.0091865696 | H14: ='Data Sheet'!G19/'Data Sheet'!G$17 -> 0.023611438 | I14: ='Data Sheet'!H19/'Data Sheet'!H$17 -> 0.014429254 | J14: ='Data Sheet'!I19/'Data Sheet'!I$17 -> 0.0043795327 | ... L14: ='Data Sheet'!K19/'Data Sheet'!K$17 -> 0.0086649161
B15: =IFERROR('Data Sheet'!A20,0) -> Power and Fuel | C15: ='Data Sheet'!B20/'Data Sheet'!B$17 -> 0.0074804081 | D15: ='Data Sheet'!C20/'Data Sheet'!C$17 -> 0.0065431032 | E15: ='Data Sheet'!D20/'Data Sheet'!D$17 -> 0.0058460941 | F15: ='Data Sheet'!E20/'Data Sheet'!E$17 -> 0.0068347035 | G15: ='Data Sheet'!F20/'Data Sheet'!F$17 -> 0.0068672585 | H15: ='Data Sheet'!G20/'Data Sheet'!G$17 -> 0.0060754442 | I15: ='Data Sheet'!H20/'Data Sheet'!H$17 -> 0.0054166752 | J15: ='Data Sheet'!I20/'Data Sheet'!I$17 -> 0.0050525613 | ... L15: ='Data Sheet'!K20/'Data Sheet'!K$17 -> 0.0047444801
B16: =IFERROR('Data Sheet'!A21,0) -> Other Mfr. Exp | C16: ='Data Sheet'!B21/'Data Sheet'!B$17 -> 0.028146291 | D16: ='Data Sheet'!C21/'Data Sheet'!C$17 -> 0.024609859 | E16: ='Data Sheet'!D21/'Data Sheet'!D$17 -> 0.023509307 | F16: ='Data Sheet'!E21/'Data Sheet'!E$17 -> 0.026894803 | G16: ='Data Sheet'!F21/'Data Sheet'!F$17 -> 0.028030563 | H16: ='Data Sheet'!G21/'Data Sheet'!G$17 -> 0.028766047 | I16: ='Data Sheet'!H21/'Data Sheet'!H$17 -> 0.032279616 | J16: ='Data Sheet'!I21/'Data Sheet'!I$17 -> 0.027503466 | ... L16: ='Data Sheet'!K21/'Data Sheet'!K$17 -> 0.024046719
B17: =IFERROR('Data Sheet'!A22,0) -> Employee Cost | C17: ='Data Sheet'!B22/'Data Sheet'!B$17 -> 0.056728318 | D17: ='Data Sheet'!C22/'Data Sheet'!C$17 -> 0.060608301 | E17: ='Data Sheet'!D22/'Data Sheet'!D$17 -> 0.063991362 | F17: ='Data Sheet'!E22/'Data Sheet'!E$17 -> 0.071699061 | G17: ='Data Sheet'!F22/'Data Sheet'!F$17 -> 0.086936477 | H17: ='Data Sheet'!G22/'Data Sheet'!G$17 -> 0.096696807 | I17: ='Data Sheet'!H22/'Data Sheet'!H$17 -> 0.079727477 | J17: ='Data Sheet'!I22/'Data Sheet'!I$17 -> 0.069375261 | ... L17: ='Data Sheet'!K22/'Data Sheet'!K$17 -> 0.073725713
B18: =IFERROR('Data Sheet'!A23,0) -> Selling and admin | C18: ='Data Sheet'!B23/'Data Sheet'!B$17 -> 0.064372329 | D18: ='Data Sheet'!C23/'Data Sheet'!C$17 -> 0.058613522 | E18: ='Data Sheet'!D23/'Data Sheet'!D$17 -> 0.063096768 | F18: ='Data Sheet'!E23/'Data Sheet'!E$17 -> 0.066838419 | G18: ='Data Sheet'!F23/'Data Sheet'!F$17 -> 0.072885144 | H18: ='Data Sheet'!G23/'Data Sheet'!G$17 -> 0.059919613 | I18: ='Data Sheet'!H23/'Data Sheet'!H$17 -> 0.079192412 | J18: ='Data Sheet'!I23/'Data Sheet'!I$17 -> 0.080637411 | ... L18: ='Data Sheet'!K23/'Data Sheet'!K$17 -> 0.088479016
B19: =IFERROR('Data Sheet'!A24,0) -> Other Expenses | C19: ='Data Sheet'!B24/'Data Sheet'!B$17 -> 0.013039689 | D19: ='Data Sheet'!C24/'Data Sheet'!C$17 -> 0.013549712 | E19: ='Data Sheet'!D24/'Data Sheet'!D$17 -> 0.012116061 | F19: ='Data Sheet'!E24/'Data Sheet'!E$17 -> 0.014864663 | G19: ='Data Sheet'!F24/'Data Sheet'!F$17 -> 0.020717577 | H19: ='Data Sheet'!G24/'Data Sheet'!G$17 -> 0.017612825 | I19: ='Data Sheet'!H24/'Data Sheet'!H$17 -> 0.013289208 | J19: ='Data Sheet'!I24/'Data Sheet'!I$17 -> 0.0098309258 | ... L19: ='Data Sheet'!K24/'Data Sheet'!K$17 -> 0.012561505
B20: =IFERROR('Data Sheet'!A25,0) -> Other Income | C20: ='Data Sheet'!B25/'Data Sheet'!B$17 -> 0.052792113 | D20: ='Data Sheet'!C25/'Data Sheet'!C$17 -> 0.059209254 | E20: ='Data Sheet'!D25/'Data Sheet'!D$17 -> 0.059750406 | F20: ='Data Sheet'!E25/'Data Sheet'!E$17 -> 0.071517374 | G20: ='Data Sheet'!F25/'Data Sheet'!F$17 -> 0.062535096 | H20: ='Data Sheet'!G25/'Data Sheet'!G$17 -> 0.055312 | I20: ='Data Sheet'!H25/'Data Sheet'!H$17 -> 0.0481315 | J20: ='Data Sheet'!I25/'Data Sheet'!I$17 -> 0.062881089 | ... L20: ='Data Sheet'!K25/'Data Sheet'!K$17 -> 0.10567743
B21: =IFERROR('Data Sheet'!A26,0) -> Depreciation | C21: ='Data Sheet'!B26/'Data Sheet'!B$17 -> 0.022126976 | D21: ='Data Sheet'!C26/'Data Sheet'!C$17 -> 0.021868637 | E21: ='Data Sheet'!D26/'Data Sheet'!D$17 -> 0.024908087 | F21: ='Data Sheet'!E26/'Data Sheet'!E$17 -> 0.030650011 | G21: ='Data Sheet'!F26/'Data Sheet'!F$17 -> 0.041682052 | H21: ='Data Sheet'!G26/'Data Sheet'!G$17 -> 0.051687146 | I21: ='Data Sheet'!H26/'Data Sheet'!H$17 -> 0.043885945 | J21: ='Data Sheet'!I26/'Data Sheet'!I$17 -> 0.036435635 | ... L21: ='Data Sheet'!K26/'Data Sheet'!K$17 -> 0.038649522
B22: =IFERROR('Data Sheet'!A27,0) -> Interest | C22: ='Data Sheet'!B27/'Data Sheet'!B$17 -> 0.00034340548 | D22: ='Data Sheet'!C27/'Data Sheet'!C$17 -> 0.00050615922 | E22: ='Data Sheet'!D27/'Data Sheet'!D$17 -> 0.00059565241 | F22: ='Data Sheet'!E27/'Data Sheet'!E$17 -> 0.00074818364 | G22: ='Data Sheet'!F27/'Data Sheet'!F$17 -> 0.002062581 | H22: ='Data Sheet'!G27/'Data Sheet'!G$17 -> 0.0018863922 | I22: ='Data Sheet'!H27/'Data Sheet'!H$17 -> 0.0018236852 | J22: ='Data Sheet'!I27/'Data Sheet'!I$17 -> 0.0019401503 | ... L22: ='Data Sheet'!K27/'Data Sheet'!K$17 -> 0.0028796498
B23: =IFERROR('Data Sheet'!A28,0) -> Profit before tax | C23: ='Data Sheet'!B28/'Data Sheet'!B$17 -> 0.30403048 | D23: ='Data Sheet'!C28/'Data Sheet'!C$17 -> 0.34597689 | E23: ='Data Sheet'!D28/'Data Sheet'!D$17 -> 0.34753641 | F23: ='Data Sheet'!E28/'Data Sheet'!E$17 -> 0.33655913 | G23: ='Data Sheet'!F28/'Data Sheet'!F$17 -> 0.25726437 | H23: ='Data Sheet'!G28/'Data Sheet'!G$17 -> 0.20622911 | I23: ='Data Sheet'!H28/'Data Sheet'!H$17 -> 0.21388098 | J23: ='Data Sheet'!I28/'Data Sheet'!I$17 -> 0.26309255 | ... L23: ='Data Sheet'!K28/'Data Sheet'!K$17 -> 0.31441229
... B26: =IFERROR('Data Sheet'!A31,0) -> Dividend Amount | C26: ='Data Sheet'!B31/'Data Sheet'!B$17 -> 0.043994778 | D26: ='Data Sheet'!C31/'Data Sheet'!C$17 -> 0.038687057 | E26: ='Data Sheet'!D31/'Data Sheet'!D$17 -> 0.033448002 | F26: ='Data Sheet'!E31/'Data Sheet'!E$17 -> 0.03480636 | G26: ='Data Sheet'!F31/'Data Sheet'!F$17 -> 0.037280496 | H26: ='Data Sheet'!G31/'Data Sheet'!G$17 -> 0.053278825 | I26: ='Data Sheet'!H31/'Data Sheet'!H$17 -> 0.055753494 | J26: ='Data Sheet'!I31/'Data Sheet'!I$17 -> 0.070069062 | ... L26: ='Data Sheet'!K31/'Data Sheet'!K$17 -> 0.10171512
B27: EBIDTA | C27: ='Data Sheet'!B32/'Data Sheet'!B$17 -> 0.32650086 | D27: ='Data Sheet'!C32/'Data Sheet'!C$17 -> 0.36181142 | E27: ='Data Sheet'!D32/'Data Sheet'!D$17 -> 0.34849458 | F27: ='Data Sheet'!E32/'Data Sheet'!E$17 -> 0.36616903 | G27: ='Data Sheet'!F32/'Data Sheet'!F$17 -> 0.301009 | H27: ='Data Sheet'!G32/'Data Sheet'!G$17 -> 0.25980265 | I27: ='Data Sheet'!H32/'Data Sheet'!H$17 -> 0.25959061 | J27: ='Data Sheet'!I32/'Data Sheet'!I$17 -> 0.30146834 | ... L27: ='Data Sheet'!K32/'Data Sheet'!K$17 -> 0.35594146
B29: ="Common size Balance sheet statement - "&'Data Sheet'!B1 -> Common size Balance sheet statement - EICHER MOTORS LTD
B31: Particulars | C31: 42460 | D31: 42825 | E31: 43190 | F31: 43555 | G31: 43921 | H31: 44286 | I31: 44651 | J31: 45016 | K31: 45382 | L31: 45747
B32: Total Liabilaty | C32: ='Data Sheet'!B61/'Data Sheet'!B$61 -> 1 | D32: ='Data Sheet'!C61/'Data Sheet'!C$61 -> 1 | E32: ='Data Sheet'!D61/'Data Sheet'!D$61 -> 1 | F32: ='Data Sheet'!E61/'Data Sheet'!E$61 -> 1 | G32: ='Data Sheet'!F61/'Data Sheet'!F$61 -> 1 | H32: ='Data Sheet'!G61/'Data Sheet'!G$61 -> 1 | I32: ='Data Sheet'!H61/'Data Sheet'!H$61 -> 1 | J32: ='Data Sheet'!I61/'Data Sheet'!I$61 -> 1 | ... L32: ='Data Sheet'!K61/'Data Sheet'!K$61 -> 1
